``trio.MultiError`` has been removed in favor of the built-in :exc:`BaseExceptionGroup`
(and its derivative :exc:`ExceptionGroup`), falling back to the backport_ on
Python < 3.11.
See the :ref:`updated documentation <exceptiongroups>` on how to deal with exception
groups.

.. _backport: https://pypi.org/project/exceptiongroup/
